TypeError: This app has encountered an error. The original error message is redacted to prevent data leaks. Full error details have been recorded in the logs (if you're on Streamlit Cloud, click on 'Manage app' in the lower right of your app).
Traceback:
File "/mount/src/penerapan-algoritma-ml-untuk-prediksi-penjualan/predict.py", line 1215, in <module>
    main()
    ~~~~^^
File "/mount/src/penerapan-algoritma-ml-untuk-prediksi-penjualan/predict.py", line 735, in main
    with st.spinner("""
         ~~~~~~~~~~^^^^
        <div class="loading-container">
        ^^^^^^^^^^^^^^^^^^^^^^^^^^^^^^^
            <div class="loading-spinner"></div>
            ^^^^^^^^^^^^^^^^^^^^^^^^^^^^^^^^^^^
        </div>
        ^^^^^^
    """, unsafe_allow_html=True):
    ^^^^^^^^^^^^^^^^^^^^^^^^^^^^
File "/usr/local/lib/python3.13/contextlib.py", line 305, in helper
    return _GeneratorContextManager(func, args, kwds)
File "/usr/local/lib/python3.13/contextlib.py", line 109, in __init__
    self.gen = func(*args, **kwds)
               ~~~~^^^^^^^^^^^^^^^
